<?xml version="1.0"?>
<robot xmlns:xacro="http://www.ros.org/wiki/xacro" name="gripper">
    
    <link name="palm">
        <visual>
            <geometry>
                <mesh filename="package://yara_meshes/files/palm.obj"/>
            </geometry>                     
        </visual>
        <collision>
            <geometry>
                <mesh filename="package://yara_meshes/files/palm.obj"/>
            </geometry>   
        </collision>
    </link>

    <link name="servo_gear">
        <visual>
            <geometry>
                <box size="0.001 0.001 0.0005"/>
            </geometry>
        </visual>
    </link>

    <joint name="palm_to_servo_gear" type="revolute">
        <axis xyz="0 0 1"/>
        <limit effort="1000.0" lower="${-pi/2}" upper="${pi/2}" velocity="0.5"/>
        <parent link="palm"/>
        <child link="servo_gear"/>
        <origin rpy="0 0 0" xyz="0 0.0125 0.005"/>
    </joint>

    <link name="right_gear">
        <visual>
            <geometry>
                <mesh filename="package://yara_meshes/files/right_gear.obj"/>
            </geometry>                     
        </visual>
        <collision>
            <geometry>
                <mesh filename="package://yara_meshes/files/right_gear.obj"/>
            </geometry>   
        </collision>
    </link>

    <joint name="palm_to_right_gear" type="revolute">
        <axis xyz="0 0 1"/>
        <limit effort="1000.0" lower="${-pi/2}" upper="${pi/2}" velocity="0.5"/>
        <parent link="palm"/>
        <child link="right_gear"/>
        <origin rpy="0 0 0" xyz="0.014 0.02 0.002"/>
        <mimic joint="palm_to_servo_gear" multiplier="1"/> 
    </joint>

    <link name="left_gear">
        <visual>
            <geometry>
                <mesh filename="package://yara_meshes/files/left_gear.obj"/>
            </geometry>                     
        </visual>
        <collision>
            <geometry>
                <mesh filename="package://yara_meshes/files/left_gear.obj"/>
            </geometry>
        </collision>
    </link>    

    <joint name="palm_to_left_gear" type="revolute">
        <axis xyz="0 0 1"/>
        <limit effort="1000.0" lower="${-pi/2}" upper="${pi/2}" velocity="0.5"/>
        <parent link="palm"/>
        <child link="left_gear"/>
        <origin rpy="0 0 0" xyz="-0.014 0.02 0.002"/>
        <mimic joint="palm_to_servo_gear" multiplier="-1"/> 
    </joint>

    <link name="right_hinge">
        <visual>
            <geometry>
                <mesh filename="package://yara_meshes/files/right_hinge.obj"/>
            </geometry>                     
        </visual>
        <collision>
            <geometry>
                <mesh filename="package://yara_meshes/files/right_hinge.obj"/>
            </geometry>   
        </collision>
    </link>

    <joint name="palm_to_right_hinge" type="revolute">
        <axis xyz="0 0 1"/>
        <limit effort="1000.0" lower="${-pi/2}" upper="${pi/2}" velocity="0.5"/>
        <parent link="palm"/>
        <child link="right_hinge"/>
        <origin rpy="0 0 0" xyz="0.004 0.042 0.002"/>
        <mimic joint="palm_to_right_gear" multiplier="1"/> 
    </joint>

    <link name="left_hinge">
        <visual>
            <geometry>
                <mesh filename="package://yara_meshes/files/left_hinge.obj"/>
            </geometry>                     
        </visual>
        <collision>
            <geometry>
                <mesh filename="package://yara_meshes/files/left_hinge.obj"/>
            </geometry>   
        </collision>
    </link>    

    <joint name="palm_to_left_hinge" type="revolute">
        <axis xyz="0 0 1"/>
        <limit effort="1000.0" lower="${-pi/2}" upper="${pi/2}" velocity="0.5"/>
        <parent link="palm"/>
        <child link="left_hinge"/>
        <origin rpy="0 0 0" xyz="-0.004 0.042 0.002"/>
        <mimic joint="palm_to_left_gear" multiplier="1"/> 
    </joint>

    <link name="right_finger">
        <visual>
            <geometry>
                <mesh filename="package://yara_meshes/files/right_finger.obj"/>
            </geometry>                 
        </visual>
        <collision>
            <geometry>
                <mesh filename="package://yara_meshes/files/right_finger.obj"/>
            </geometry>               
        </collision>
    </link>

    <joint name="right_gear_to_right_finger" type="revolute">
        <axis xyz="0 0 1"/>
        <limit effort="1000.0" lower="${-pi/2}" upper="${pi/2}" velocity="0.5"/>
        <parent link="right_gear"/>
        <child link="right_finger"/>
        <origin rpy="0 0 0" xyz="0.022 0 0"/>
        <mimic joint="palm_to_right_gear" multiplier="-1"/> 
    </joint>

    <link name="left_finger">
        <visual>
            <geometry>
                <mesh filename="package://yara_meshes/files/left_finger.obj"/>
            </geometry>                 
        </visual>
        <collision>
            <geometry>
                <mesh filename="package://yara_meshes/files/left_finger.obj"/>
            </geometry>               
        </collision>
    </link>

    <joint name="left_gear_to_left_finger" type="revolute">
        <axis xyz="0 0 1"/>
        <limit effort="1000.0" lower="${-pi/2}" upper="${pi/2}" velocity="0.5"/>
        <parent link="left_gear"/>
        <child link="left_finger"/>
        <origin rpy="0 0 0" xyz="-0.022 0 0"/>
        <mimic joint="palm_to_left_gear" multiplier="-1"/> 
    </joint>

</robot>
