<?xml version="1.0"?>
<robot xmlns:xacro="http://www.ros.org/wiki/xacro" name="yara">
    
    <link name="base_link">
        <visual>
            <geometry>
                <mesh filename="package://yara_meshes/files/base.obj"/>
            </geometry>                     
            <origin rpy="0 0 ${pi}" xyz="0 0 0"/>
        </visual>
        <collision>
            <geometry>
                <mesh filename="package://yara_meshes/files/base.obj"/>
            </geometry>   
            <origin rpy="0 0 ${pi}" xyz="0 0 0"/>
        </collision>
    </link>

    <link name="link_1">
        <visual>
            <geometry>
                <mesh filename="package://yara_meshes/files/Link1.obj"/>
            </geometry>            
        </visual>
        <collision>
            <geometry>
                <mesh filename="package://yara_meshes/files/Link1.obj"/>
            </geometry>   
        </collision>
    </link>

    <joint name="base_to_link_1" type="revolute">
        <axis xyz="0 0 1"/>
        <limit effort="1000.0" lower="${-pi/2}" upper="${pi/2}" velocity="0.5"/>
        <parent link="base_link"/>
        <child link="link_1"/>
        <origin rpy="0 0 ${pi}" xyz="0 0 0.054"/>
    </joint>

    <link name="link_2">
        <visual>
            <geometry>
                <mesh filename="package://yara_meshes/files/Link2.obj"/>
            </geometry>            
        </visual>
        <collision>
            <geometry>
                <mesh filename="package://yara_meshes/files/Link2.obj"/>
            </geometry>   
        </collision>
    </link>

    <joint name="link_1_to_link_2" type="revolute">
        <axis xyz="-1 0 0"/>
        <limit effort="1000.0" lower="${-pi/2}" upper="${pi/2}" velocity="0.5"/>
        <parent link="link_1"/>
        <child link="link_2"/>
        <origin rpy="0 0 0" xyz="0 -0.017 0.056"/>
    </joint>

    <link name="link_3">
        <visual>
            <geometry>
                <mesh filename="package://yara_meshes/files/Link3.obj"/>
            </geometry>            
        </visual>
        <collision>
            <geometry>
                <mesh filename="package://yara_meshes/files/Link3.obj"/>
            </geometry>   
        </collision>
    </link>

    <joint name="link_2_to_link_3" type="revolute">
        <axis xyz="-1 0 0"/>
        <limit effort="1000.0" lower="${-pi/2}" upper="${pi/2}" velocity="0.5"/>
        <parent link="link_2"/>
        <child link="link_3"/>
        <origin rpy="0 0 0" xyz="0 0 0.12"/>
    </joint>

    <link name="link_4">
        <visual>
            <geometry>
                <mesh filename="package://yara_meshes/files/Link4.obj"/>
            </geometry>            
        </visual>
        <collision>
            <geometry>
                <mesh filename="package://yara_meshes/files/Link4.obj"/>
            </geometry>   
        </collision>
    </link>

    <joint name="link_3_to_link_4" type="revolute">
        <axis xyz="0 -1 0"/>
        <limit effort="1000.0" lower="${-pi/2}" upper="${pi/2}" velocity="0.5"/>
        <parent link="link_3"/>
        <child link="link_4"/>
        <origin rpy="0 0 0" xyz="0 -0.024 0.044"/>
    </joint>

    <link name="link_5">
        <visual>
            <geometry>
                <mesh filename="package://yara_meshes/files/Link5.obj"/>
            </geometry>            
        </visual>
        <collision>
            <geometry>
                <mesh filename="package://yara_meshes/files/Link5.obj"/>
            </geometry>   
        </collision>
    </link>

    <joint name="link_4_to_link_5" type="revolute">
        <axis xyz="1 0 0"/>
        <limit effort="1000.0" lower="${-pi/2}" upper="${pi/2}" velocity="0.5"/>
        <parent link="link_4"/>
        <child link="link_5"/>
        <origin rpy="0 0 0" xyz="0 -0.146 0.004"/>
    </joint>

    <!-- <link name="link_6">
        <visual>
            <geometry>
                <mesh filename="package://yara_meshes/files/Link6.obj"/>
            </geometry>            
        </visual>
        <collision>
            <geometry>
                <mesh filename="package://yara_meshes/files/Link6.obj"/>
            </geometry>   
        </collision>
    </link>

    <joint name="link_5_to_link_6" type="revolute">
        <axis xyz="0 -1 0"/>
        <limit effort="1000.0" lower="${-pi/2}" upper="${pi/2}" velocity="0.5"/>
        <parent link="link_5"/>
        <child link="link_6"/>
        <origin rpy="0 0 0" xyz="0 -0.042 0"/>
    </joint> -->

    <!-- <link name="penHolder">
        <visual>
            <geometry>
                <mesh filename="package://yara_meshes/files/PenHolder.obj"/>
            </geometry>            
        </visual>
        <collision>
            <geometry>
                <mesh filename="package://yara_meshes/files/PenHolder.obj"/>
            </geometry>   
        </collision>
    </link>

    <joint name="link_6_to_penHolder" type="fixed">
        <parent link="link_6"/>
        <child link="penHolder"/>
        <origin rpy="0 0 0" xyz="0 -0.01 0.001"/>
    </joint>

    <link name="pen">
        <visual>
            <geometry>
                <mesh filename="package://yara_meshes/files/Pen.obj"/>
            </geometry>            
        </visual>
        <collision>
            <geometry>
                <mesh filename="package://yara_meshes/files/Pen.obj"/>
            </geometry>   
        </collision>
    </link>

    <joint name="penHolder_to_pen" type="fixed">
        <parent link="penHolder"/>
        <child link="pen"/>
        <origin rpy="0 0 0" xyz="0 -0.001 -0.058"/>
    </joint> -->

    <xacro:include filename="$(find yara_meshes)/files/gripper.xacro"/> 

    <joint name="link_5_to_palm" type="revolute">
        <axis xyz="0 1 0"/>
        <limit effort="1000.0" lower="${-pi/2}" upper="${pi/2}" velocity="0.5"/>
        <parent link="link_5"/>
        <child link="palm"/>
        <origin rpy="0 0 ${pi}" xyz="0 -0.042 0"/>
    </joint>

    <link name="grabbing_point">
        <visual>
            <geometry>
                <sphere radius="0.0025"/>
            </geometry>
        </visual>
    </link>

    <joint name="palm_to_grabbing_point" type="fixed">
        <parent link="palm"/>
        <child link="grabbing_point"/>
        <origin rpy="0 0 0" xyz="0 0.08103 0.00156"/>
    </joint>

</robot>
