<?xml version="1.0" ?>
<!-- =================================================================================== -->
<!-- |    This document was autogenerated by xacro from yara.xacro                     | -->
<!-- |    EDITING THIS FILE BY HAND IS NOT RECOMMENDED                                 | -->
<!-- =================================================================================== -->
<robot name="yara">
  <link name="base_link">
    <visual>
      <geometry>
        <mesh filename="package://yara_meshes/files/base.obj"/>
      </geometry>
      <origin rpy="0 0 3.141592653589793" xyz="0 0 0"/>
    </visual>
    <collision>
      <geometry>
        <mesh filename="package://yara_meshes/files/base.obj"/>
      </geometry>
      <origin rpy="0 0 3.141592653589793" xyz="0 0 0"/>
    </collision>
  </link>
  <link name="link_1">
    <visual>
      <geometry>
        <mesh filename="package://yara_meshes/files/Link1.obj"/>
      </geometry>
    </visual>
    <collision>
      <geometry>
        <mesh filename="package://yara_meshes/files/Link1.obj"/>
      </geometry>
    </collision>
  </link>
  <joint name="base_to_link_1" type="revolute">
    <axis xyz="0 0 1"/>
    <limit effort="1000.0" lower="-1.5707963267948966" upper="1.5707963267948966" velocity="0.5"/>
    <parent link="base_link"/>
    <child link="link_1"/>
    <origin rpy="0 0 3.141592653589793" xyz="0 0 0.054"/>
  </joint>
  <link name="link_2">
    <visual>
      <geometry>
        <mesh filename="package://yara_meshes/files/Link2.obj"/>
      </geometry>
    </visual>
    <collision>
      <geometry>
        <mesh filename="package://yara_meshes/files/Link2.obj"/>
      </geometry>
    </collision>
  </link>
  <joint name="link_1_to_link_2" type="revolute">
    <axis xyz="-1 0 0"/>
    <limit effort="1000.0" lower="-1.5707963267948966" upper="1.5707963267948966" velocity="0.5"/>
    <parent link="link_1"/>
    <child link="link_2"/>
    <origin rpy="0 0 0" xyz="0 -0.017 0.056"/>
  </joint>
  <link name="link_3">
    <visual>
      <geometry>
        <mesh filename="package://yara_meshes/files/Link3.obj"/>
      </geometry>
    </visual>
    <collision>
      <geometry>
        <mesh filename="package://yara_meshes/files/Link3.obj"/>
      </geometry>
    </collision>
  </link>
  <joint name="link_2_to_link_3" type="revolute">
    <axis xyz="-1 0 0"/>
    <limit effort="1000.0" lower="-1.5707963267948966" upper="1.5707963267948966" velocity="0.5"/>
    <parent link="link_2"/>
    <child link="link_3"/>
    <origin rpy="0 0 0" xyz="0 0 0.12"/>
  </joint>
  <link name="link_4">
    <visual>
      <geometry>
        <mesh filename="package://yara_meshes/files/Link4.obj"/>
      </geometry>
    </visual>
    <collision>
      <geometry>
        <mesh filename="package://yara_meshes/files/Link4.obj"/>
      </geometry>
    </collision>
  </link>
  <joint name="link_3_to_link_4" type="revolute">
    <axis xyz="0 -1 0"/>
    <limit effort="1000.0" lower="-1.5707963267948966" upper="1.5707963267948966" velocity="0.5"/>
    <parent link="link_3"/>
    <child link="link_4"/>
    <origin rpy="0 0 0" xyz="0 -0.024 0.044"/>
  </joint>
  <link name="link_5">
    <visual>
      <geometry>
        <mesh filename="package://yara_meshes/files/Link5.obj"/>
      </geometry>
    </visual>
    <collision>
      <geometry>
        <mesh filename="package://yara_meshes/files/Link5.obj"/>
      </geometry>
    </collision>
  </link>
  <joint name="link_4_to_link_5" type="revolute">
    <axis xyz="1 0 0"/>
    <limit effort="1000.0" lower="-1.5707963267948966" upper="1.5707963267948966" velocity="0.5"/>
    <parent link="link_4"/>
    <child link="link_5"/>
    <origin rpy="0 0 0" xyz="0 -0.146 0.004"/>
  </joint>
  <!-- <link name="link_6">
        <visual>
            <geometry>
                <mesh filename="package://yara_meshes/files/Link6.obj"/>
            </geometry>            
        </visual>
        <collision>
            <geometry>
                <mesh filename="package://yara_meshes/files/Link6.obj"/>
            </geometry>   
        </collision>
    </link>

    <joint name="link_5_to_link_6" type="revolute">
        <axis xyz="0 -1 0"/>
        <limit effort="1000.0" lower="${-pi/2}" upper="${pi/2}" velocity="0.5"/>
        <parent link="link_5"/>
        <child link="link_6"/>
        <origin rpy="0 0 0" xyz="0 -0.042 0"/>
    </joint> -->
  <!-- <link name="penHolder">
        <visual>
            <geometry>
                <mesh filename="package://yara_meshes/files/PenHolder.obj"/>
            </geometry>            
        </visual>
        <collision>
            <geometry>
                <mesh filename="package://yara_meshes/files/PenHolder.obj"/>
            </geometry>   
        </collision>
    </link>

    <joint name="link_6_to_penHolder" type="fixed">
        <parent link="link_6"/>
        <child link="penHolder"/>
        <origin rpy="0 0 0" xyz="0 -0.01 0.001"/>
    </joint>

    <link name="pen">
        <visual>
            <geometry>
                <mesh filename="package://yara_meshes/files/Pen.obj"/>
            </geometry>            
        </visual>
        <collision>
            <geometry>
                <mesh filename="package://yara_meshes/files/Pen.obj"/>
            </geometry>   
        </collision>
    </link>

    <joint name="penHolder_to_pen" type="fixed">
        <parent link="penHolder"/>
        <child link="pen"/>
        <origin rpy="0 0 0" xyz="0 -0.001 -0.058"/>
    </joint> -->
  <link name="palm">
    <visual>
      <geometry>
        <mesh filename="package://yara_meshes/files/palm.obj"/>
      </geometry>
    </visual>
    <collision>
      <geometry>
        <mesh filename="package://yara_meshes/files/palm.obj"/>
      </geometry>
    </collision>
  </link>
  <link name="servo_gear">
    <visual>
      <geometry>
        <box size="0.001 0.001 0.0005"/>
      </geometry>
    </visual>
  </link>
  <joint name="palm_to_servo_gear" type="revolute">
    <axis xyz="0 0 1"/>
    <limit effort="1000.0" lower="-1.5707963267948966" upper="1.5707963267948966" velocity="0.5"/>
    <parent link="palm"/>
    <child link="servo_gear"/>
    <origin rpy="0 0 0" xyz="0 0.0125 0.005"/>
  </joint>
  <link name="right_gear">
    <visual>
      <geometry>
        <mesh filename="package://yara_meshes/files/right_gear.obj"/>
      </geometry>
    </visual>
    <collision>
      <geometry>
        <mesh filename="package://yara_meshes/files/right_gear.obj"/>
      </geometry>
    </collision>
  </link>
  <joint name="palm_to_right_gear" type="revolute">
    <axis xyz="0 0 1"/>
    <limit effort="1000.0" lower="-1.5707963267948966" upper="1.5707963267948966" velocity="0.5"/>
    <parent link="palm"/>
    <child link="right_gear"/>
    <origin rpy="0 0 0" xyz="0.014 0.02 0.002"/>
    <mimic joint="palm_to_servo_gear" multiplier="1"/>
  </joint>
  <link name="left_gear">
    <visual>
      <geometry>
        <mesh filename="package://yara_meshes/files/left_gear.obj"/>
      </geometry>
    </visual>
    <collision>
      <geometry>
        <mesh filename="package://yara_meshes/files/left_gear.obj"/>
      </geometry>
    </collision>
  </link>
  <joint name="palm_to_left_gear" type="revolute">
    <axis xyz="0 0 1"/>
    <limit effort="1000.0" lower="-1.5707963267948966" upper="1.5707963267948966" velocity="0.5"/>
    <parent link="palm"/>
    <child link="left_gear"/>
    <origin rpy="0 0 0" xyz="-0.014 0.02 0.002"/>
    <mimic joint="palm_to_servo_gear" multiplier="-1"/>
  </joint>
  <link name="right_hinge">
    <visual>
      <geometry>
        <mesh filename="package://yara_meshes/files/right_hinge.obj"/>
      </geometry>
    </visual>
    <collision>
      <geometry>
        <mesh filename="package://yara_meshes/files/right_hinge.obj"/>
      </geometry>
    </collision>
  </link>
  <joint name="palm_to_right_hinge" type="revolute">
    <axis xyz="0 0 1"/>
    <limit effort="1000.0" lower="-1.5707963267948966" upper="1.5707963267948966" velocity="0.5"/>
    <parent link="palm"/>
    <child link="right_hinge"/>
    <origin rpy="0 0 0" xyz="0.004 0.042 0.002"/>
    <mimic joint="palm_to_right_gear" multiplier="1"/>
  </joint>
  <link name="left_hinge">
    <visual>
      <geometry>
        <mesh filename="package://yara_meshes/files/left_hinge.obj"/>
      </geometry>
    </visual>
    <collision>
      <geometry>
        <mesh filename="package://yara_meshes/files/left_hinge.obj"/>
      </geometry>
    </collision>
  </link>
  <joint name="palm_to_left_hinge" type="revolute">
    <axis xyz="0 0 1"/>
    <limit effort="1000.0" lower="-1.5707963267948966" upper="1.5707963267948966" velocity="0.5"/>
    <parent link="palm"/>
    <child link="left_hinge"/>
    <origin rpy="0 0 0" xyz="-0.004 0.042 0.002"/>
    <mimic joint="palm_to_left_gear" multiplier="1"/>
  </joint>
  <link name="right_finger">
    <visual>
      <geometry>
        <mesh filename="package://yara_meshes/files/right_finger.obj"/>
      </geometry>
    </visual>
    <collision>
      <geometry>
        <mesh filename="package://yara_meshes/files/right_finger.obj"/>
      </geometry>
    </collision>
  </link>
  <joint name="right_gear_to_right_finger" type="revolute">
    <axis xyz="0 0 1"/>
    <limit effort="1000.0" lower="-1.5707963267948966" upper="1.5707963267948966" velocity="0.5"/>
    <parent link="right_gear"/>
    <child link="right_finger"/>
    <origin rpy="0 0 0" xyz="0.022 0 0"/>
    <mimic joint="palm_to_right_gear" multiplier="-1"/>
  </joint>
  <link name="left_finger">
    <visual>
      <geometry>
        <mesh filename="package://yara_meshes/files/left_finger.obj"/>
      </geometry>
    </visual>
    <collision>
      <geometry>
        <mesh filename="package://yara_meshes/files/left_finger.obj"/>
      </geometry>
    </collision>
  </link>
  <joint name="left_gear_to_left_finger" type="revolute">
    <axis xyz="0 0 1"/>
    <limit effort="1000.0" lower="-1.5707963267948966" upper="1.5707963267948966" velocity="0.5"/>
    <parent link="left_gear"/>
    <child link="left_finger"/>
    <origin rpy="0 0 0" xyz="-0.022 0 0"/>
    <mimic joint="palm_to_left_gear" multiplier="-1"/>
  </joint>
  <joint name="link_5_to_palm" type="revolute">
    <axis xyz="0 1 0"/>
    <limit effort="1000.0" lower="-1.5707963267948966" upper="1.5707963267948966" velocity="0.5"/>
    <parent link="link_5"/>
    <child link="palm"/>
    <origin rpy="0 0 3.141592653589793" xyz="0 -0.042 0"/>
  </joint>
  <link name="grabbing_point">
    <visual>
      <geometry>
        <sphere radius="0.0025"/>
      </geometry>
    </visual>
  </link>
  <joint name="palm_to_grabbing_point" type="fixed">
    <parent link="palm"/>
    <child link="grabbing_point"/>
    <origin rpy="0 0 0" xyz="0 0.08103 0.00156"/>
  </joint>
</robot>
