<?xml version="1.0" encoding="utf-8"?>
<!-- =================================================================================== -->
<!-- |    This document was autogenerated by xacro from yara.urdf.xacro                | -->
<!-- |    EDITING THIS FILE BY HAND IS NOT RECOMMENDED                                 | -->
<!-- =================================================================================== -->
<robot name="yara">
  <link name="base_link">
    <visual>
      <geometry>
        <mesh filename="package://yara_meshes/files/base.obj"/>
      </geometry>
      <origin rpy="0 0 3.14159265359" xyz="0 0 0"/>
    </visual>
  </link>
  <link name="link_1">
    <visual>
      <geometry>
        <mesh filename="package://yara_meshes/files/link1.obj"/>
      </geometry>
      <origin rpy="0 0 3.14159265359" xyz="0 0 -0.054355"/>
    </visual>
  </link>
  <joint name="base_to_link_1" type="revolute">
    <axis xyz="0 0 1"/>
    <limit effort="1000.0" lower="-1.57079632679" upper="1.57079632679" velocity="0.5"/>
    <parent link="base_link"/>
    <child link="link_1"/>
    <origin rpy="0 0 0" xyz="0 0 0.054355"/>
  </joint>
  <link name="link_2">
    <visual>
      <geometry>
        <mesh filename="package://yara_meshes/files/link2.obj"/>
      </geometry>
      <origin rpy="0 0 3.14159265359" xyz="0 -.017415 -.109967"/>
    </visual>
  </link>
  <joint name="link_1_to_link_2" type="revolute">
    <axis xyz="1 0 0"/>
    <limit effort="1000.0" lower="-1.57079632679" upper="1.57079632679" velocity="0.5"/>
    <parent link="link_1"/>
    <child link="link_2"/>
    <origin rpy="0 0 0" xyz="0 .017415 0.055612"/>
  </joint>
  <link name="link_3">
    <visual>
      <geometry>
        <mesh filename="package://yara_meshes/files/link3.obj"/>
      </geometry>
      <origin rpy="0 0 3.14159265359" xyz="0 -.017415 -.229967"/>
    </visual>
  </link>
  <joint name="link_2_to_link_3" type="revolute">
    <axis xyz="1 0 0"/>
    <limit effort="1000.0" lower="-1.57079632679" upper="1.57079632679" velocity="0.5"/>
    <parent link="link_2"/>
    <child link="link_3"/>
    <origin rpy="0 0 0" xyz="0 0 0.12"/>
  </joint>
  <link name="link_4">
    <visual>
      <geometry>
        <mesh filename="package://yara_meshes/files/link4.obj"/>
      </geometry>
      <origin rpy="0 0 3.14159265359" xyz="0 -.041358 -.273945"/>
    </visual>
  </link>
  <joint name="link_3_to_link_4" type="revolute">
    <axis xyz="0 1 0"/>
    <limit effort="1000.0" lower="-1.57079632679" upper="1.57079632679" velocity="0.5"/>
    <parent link="link_3"/>
    <child link="link_4"/>
    <origin rpy="0 0 0" xyz="0 0.023943 0.043978"/>
  </joint>
  <link name="link_5">
    <visual>
      <geometry>
        <mesh filename="package://yara_meshes/files/link5.obj"/>
      </geometry>
      <origin rpy="0 0 3.14159265359" xyz="0 -0.186507 -.277517"/>
    </visual>
  </link>
  <joint name="link_4_to_link_5" type="revolute">
    <axis xyz="-1 0 0"/>
    <limit effort="1000.0" lower="-1.57079632679" upper="1.57079632679" velocity="0.5"/>
    <parent link="link_4"/>
    <child link="link_5"/>
    <origin rpy="0 0 0" xyz="0 0.145149 0.003572"/>
  </joint>
  <link name="link_6">
    <visual>
      <geometry>
        <mesh filename="package://yara_meshes/files/link6.obj"/>
      </geometry>
      <origin rpy="0 0 3.14159265359" xyz="0 -0.228778 -.27839"/>
    </visual>
  </link>
  <joint name="link_5_to_link_6" type="revolute">
    <axis xyz="0 1 0"/>
    <limit effort="1000.0" lower="-1.57079632679" upper="1.57079632679" velocity="0.5"/>
    <parent link="link_5"/>
    <child link="link_6"/>
    <origin rpy="0 0 0" xyz="0 0.042271 0.000873"/>
  </joint>
  <link name="ee">
    <visual>
      <geometry>
        <sphere radius=".01"/>
      </geometry>
      <origin rpy="0 0 0" xyz="0 0 0"/>
    </visual>
  </link>
  <joint name="link_6_to_ee" type="fixed">
    <parent link="link_6"/>
    <child link="ee"/>
    <origin rpy="0 0 0" xyz="0 0 0"/>
  </joint>
    <transmission name="trans_base_to_link_1">
        <type>transmission_interface/SimpleTransmission</type>
        <joint name="base_to_link_1">
            <hardwareInterface>hardware_interface/PositionJointInterface</hardwareInterface>
        </joint>
        <actuator name="base_to_link_1_motor">
            <hardwareInterface>hardware_interface/PositionJointInterface</hardwareInterface>
            <mechanicalReduction>1</mechanicalReduction>
        </actuator>
    </transmission>
    <transmission name="trans_link_1_to_link_2">
        <type>transmission_interface/SimpleTransmission</type>
        <joint name="link_1_to_link_2">
            <hardwareInterface>hardware_interface/PositionJointInterface</hardwareInterface>
        </joint>
        <actuator name="link_1_to_link_2_motor">
            <hardwareInterface>hardware_interface/PositionJointInterface</hardwareInterface>
            <mechanicalReduction>1</mechanicalReduction>
        </actuator>
    </transmission>
    <transmission name="trans_link_2_to_link_3">
        <type>transmission_interface/SimpleTransmission</type>
        <joint name="link_2_to_link_3">
            <hardwareInterface>hardware_interface/PositionJointInterface</hardwareInterface>
        </joint>
        <actuator name="link_2_to_link_3_motor">
            <hardwareInterface>hardware_interface/PositionJointInterface</hardwareInterface>
            <mechanicalReduction>1</mechanicalReduction>
        </actuator>
    </transmission>
    <transmission name="trans_link_3_to_link_4">
        <type>transmission_interface/SimpleTransmission</type>
        <joint name="link_3_to_link_4">
            <hardwareInterface>hardware_interface/PositionJointInterface</hardwareInterface>
        </joint>
        <actuator name="link_3_to_link_4_motor">
            <hardwareInterface>hardware_interface/PositionJointInterface</hardwareInterface>
            <mechanicalReduction>1</mechanicalReduction>
        </actuator>
    </transmission>
    <transmission name="trans_link_4_to_link_5">
        <type>transmission_interface/SimpleTransmission</type>
        <joint name="link_4_to_link_5">
            <hardwareInterface>hardware_interface/PositionJointInterface</hardwareInterface>
        </joint>
        <actuator name="link_4_to_link_5_motor">
            <hardwareInterface>hardware_interface/PositionJointInterface</hardwareInterface>
            <mechanicalReduction>1</mechanicalReduction>
        </actuator>
    </transmission>
    <transmission name="trans_link_5_to_link_6">
        <type>transmission_interface/SimpleTransmission</type>
        <joint name="link_5_to_link_6">
            <hardwareInterface>hardware_interface/PositionJointInterface</hardwareInterface>
        </joint>
        <actuator name="link_5_to_link_6_motor">
            <hardwareInterface>hardware_interface/PositionJointInterface</hardwareInterface>
            <mechanicalReduction>1</mechanicalReduction>
        </actuator>
    </transmission>
    <gazebo>
        <plugin name="gazebo_ros_control" filename="libgazebo_ros_control.so">
            <robotNamespace>/</robotNamespace>
        </plugin>
    </gazebo>
</robot>